Workbook

Sheet Fiche décompte
A1: FICHE DE DECOMPTE DU GROUPEMENT SERTEM / DIASS INDUSTRIES — Décompte n°14
A2: Travaux d'aménagement de voiries et réseaux divers et de construction d'infrastructures structurantes de la ZESID (montants en FCFA / XOF)
A3: Taux de TVA | B3: 0.18 | C3: ← hypothèse modifiable, utilisée par toutes les colonnes de TVA éclatée
A4: Source : fiche de décompte n°14 SERTEM/DIASS (PDF). Montants en bleu = saisis depuis la fiche ; noir = formules.
F6: SERTEM GROUP SASU | H6: DIASS INDUSTRIES SARL | M6: TVA ÉCLATÉE (taux × part HT/HD) | S6: CONTRÔLES
A7: Date | B7: Libellé (APIX/DISEZ) | C7: Catégorie | D7: N° facture | E7: Montant total HT/HD | F7: Part État HT/HD 5% | G7: Part BOAD HT/HD 95% | H7: Part État HT/HD 5% | I7: Part BOAD HT/HD 95% | J7: Droits de douane | K7: Montant TVA (fiche) | L7: Montant TTC (fiche) | M7: TVA SERTEM État | N7: TVA SERTEM BOAD | O7: TVA DIASS État | P7: TVA DIASS BOAD | Q7: TVA SERTEM | R7: TVA DIASS | S7: Écart TVA (éclatée − fiche) | T7: Écart TTC (fiche − HT − TVA)
B8: Montant du contrat | C8: Contrat | E8: 27747000000 | F8: 971145000 | G8: 18451755000 | H8: 416205000 | I8: 7907895000 | J8: 1466629384 | K8: 5258453289 | L8: 34472082673 | M8: =ROUND(F8*$B$3,0) -> 174806100 | N8: =ROUND(G8*$B$3,0) -> 3321315900 | O8: =ROUND(H8*$B$3,0) -> 74916900 | P8: =ROUND(I8*$B$3,0) -> 1423421100 | Q8: =M8+N8 -> 3496122000 | R8: =O8+P8 -> 1498338000 | S8: =Q8+R8-K8 -> -263993289 | T8: =IF(C8="Net à payer","",L8-E8-K8-IF(C8="Contrat",J8,0)) -> 0
A9: 45218 | B9: Avance de démarrage 20% | C9: Avance démarrage | D9: 2023/ZESID/TVX - 01 | E9: 5549400000 | F9: 194229000 | G9: 3690351000 | H9: 83241000 | I9: 1581579000 | J9: 0 | K9: 998892000 | L9: 6548292000 | M9: =ROUND(F9*$B$3,0) -> 34961220 | N9: =ROUND(G9*$B$3,0) -> 664263180 | O9: =ROUND(H9*$B$3,0) -> 14983380 | P9: =ROUND(I9*$B$3,0) -> 284684220 | Q9: =M9+N9 -> 699224400 | R9: =O9+P9 -> 299667600 | S9: =Q9+R9-K9 -> 0 | T9: =IF(C9="Net à payer","",L9-E9-K9-IF(C9="Contrat",J9,0)) -> 0
B10: NET A PAYER | C10: Net à payer | E10: 5549400000 | F10: 194229000 | G10: 3690351000 | H10: 83241000 | I10: 1581579000 | J10: 0 | K10: 998892000 | L10: 6548292000 | M10: =ROUND(F10*$B$3,0) -> 34961220 | N10: =ROUND(G10*$B$3,0) -> 664263180 | O10: =ROUND(H10*$B$3,0) -> 14983380 | P10: =ROUND(I10*$B$3,0) -> 284684220 | Q10: =M10+N10 -> 699224400 | R10: =O10+P10 -> 299667600 | S10: =Q10+R10-K10 -> 0 | T10: =IF(C10="Net à payer","",L10-E10-K10-IF(C10="Contrat",J10,0))
A11: 45366 | B11: Décompte 01 | C11: Décompte | D11: 2024/ZESID/TVX - 03 | E11: 739323172 | F11: 35161028 | G11: 668059532 | H11: 1805131 | I11: 34297481 | J11: 0 | K11: 133078171 | L11: 872401343 | M11: =ROUND(F11*$B$3,0) -> 6328985 | N11: =ROUND(G11*$B$3,0) -> 120250716 | O11: =ROUND(H11*$B$3,0) -> 324924 | P11: =ROUND(I11*$B$3,0) -> 6173547 | Q11: =M11+N11 -> 126579701 | R11: =O11+P11 -> 6498471 | S11: =Q11+R11-K11 -> 1 | T11: =IF(C11="Net à payer","",L11-E11-K11-IF(C11="Contrat",J11,0)) -> 0
A12: 45366 | B12: Remboursement avance de démarrage Décompte 01 | C12: Remb. avance démarrage | D12: 2024/ZESID/TVX - 03 | E12: 184830793 | F12: 8790257 | G12: 167014883 | H12: 451283 | I12: 8574370 | J12: 0 | K12: 31599292 | L12: 207150914 | M12: =ROUND(F12*$B$3,0) -> 1582246 | N12: =ROUND(G12*$B$3,0) -> 30062679 | O12: =ROUND(H12*$B$3,0) -> 81231 | P12: =ROUND(I12*$B$3,0) -> 1543387 | Q12: =M12+N12 -> 31644925 | R12: =O12+P12 -> 1624618 | S12: =Q12+R12-K12 -> 1670251 | T12: =IF(C12="Net à payer","",L12-E12-K12-IF(C12="Contrat",J12,0)) -> -9279171
A13: 45366 | B13: Retenue de garantie Décompte 01 | C13: Retenue de garantie | D13: 2024/ZESID/TVX - 03 | E13: 36966159 | F13: 1758051 | G13: 33402977 | H13: 90257 | I13: 1714874 | J13: 0 | K13: 6653909 | L13: 43620067 | M13: =ROUND(F13*$B$3,0) -> 316449 | N13: =ROUND(G13*$B$3,0) -> 6012536 | O13: =ROUND(H13*$B$3,0) -> 16246 | P13: =ROUND(I13*$B$3,0) -> 308677 | Q13: =M13+N13 -> 6328985 | R13: =O13+P13 -> 324923 | S13: =Q13+R13-K13 -> -1 | T13: =IF(C13="Net à payer","",L13-E13-K13-IF(C13="Contrat",J13,0)) -> -1
B14: NET A PAYER DECOMPTE 01 | C14: Net à payer | E14: 517526220 | F14: 24612720 | G14: 467641672 | H14: 1263591 | I14: 24008237 | J14: 0 | K14: 94824971 | L14: 621630362 | M14: =ROUND(F14*$B$3,0) -> 4430290 | N14: =ROUND(G14*$B$3,0) -> 84175501 | O14: =ROUND(H14*$B$3,0) -> 227446 | P14: =ROUND(I14*$B$3,0) -> 4321483 | Q14: =M14+N14 -> 88605791 | R14: =O14+P14 -> 4548929 | S14: =Q14+R14-K14 -> -1670251 | T14: =IF(C14="Net à payer","",L14-E14-K14-IF(C14="Contrat",J14,0))
A15: 45436 | B15: Décompte 02 | C15: Décompte | D15: 2024/ZESID/TVX - 05 | E15: 483038765 | F15: 22820412 | G15: 433587825 | H15: 1331526 | I15: 25299002 | J15: 0 | K15: 86946978 | L15: 569985743 | M15: =ROUND(F15*$B$3,0) -> 4107674 | N15: =ROUND(G15*$B$3,0) -> 78045809 | O15: =ROUND(H15*$B$3,0) -> 239675 | P15: =ROUND(I15*$B$3,0) -> 4553820 | Q15: =M15+N15 -> 82153483 | R15: =O15+P15 -> 4793495 | S15: =Q15+R15-K15 -> 0 | T15: =IF(C15="Net à payer","",L15-E15-K15-IF(C15="Contrat",J15,0)) -> 0
A16: 45436 | B16: Remboursement avance de démarrage Décompte 02 | C16: Remb. avance démarrage | D16: 2024/ZESID/TVX - 05 | E16: 120759691 | F16: 5705103 | G16: 108396956 | H16: 332882 | I16: 6324750 | J16: 0 | K16: 21736744 | L16: 35624109 | M16: =ROUND(F16*$B$3,0) -> 1026919 | N16: =ROUND(G16*$B$3,0) -> 19511452 | O16: =ROUND(H16*$B$3,0) -> 59919 | P16: =ROUND(I16*$B$3,0) -> 1138455 | Q16: =M16+N16 -> 20538371 | R16: =O16+P16 -> 1198374 | S16: =Q16+R16-K16 -> 1 | T16: =IF(C16="Net à payer","",L16-E16-K16-IF(C16="Contrat",J16,0)) -> -106872326
A17: 45436 | B17: Retenue de garantie Décompte 02 | C17: Retenue de garantie | D17: 2024/ZESID/TVX - 05 | E17: 24151938 | F17: 1141021 | G17: 21679391 | H17: 66576 | I17: 1264950 | J17: 0 | K17: 4347349 | L17: 28499287 | M17: =ROUND(F17*$B$3,0) -> 205384 | N17: =ROUND(G17*$B$3,0) -> 3902290 | O17: =ROUND(H17*$B$3,0) -> 11984 | P17: =ROUND(I17*$B$3,0) -> 227691 | Q17: =M17+N17 -> 4107674 | R17: =O17+P17 -> 239675 | S17: =Q17+R17-K17 -> 0 | T17: =IF(C17="Net à payer","",L17-E17-K17-IF(C17="Contrat",J17,0)) -> 0
B18: NET A PAYER DECOMPTE 02 | C18: Net à payer | E18: 338127136 | F18: 15974288 | G18: 303511478 | H18: 932068 | I18: 17709301 | J18: 0 | K18: 60862884 | L18: 398990020 | M18: =ROUND(F18*$B$3,0) -> 2875372 | N18: =ROUND(G18*$B$3,0) -> 54632066 | O18: =ROUND(H18*$B$3,0) -> 167772 | P18: =ROUND(I18*$B$3,0) -> 3187674 | Q18: =M18+N18 -> 57507438 | R18: =O18+P18 -> 3355446 | S18: =Q18+R18-K18 -> 0 | T18: =IF(C18="Net à payer","",L18-E18-K18-IF(C18="Contrat",J18,0))
A19: 45467 | B19: Décompte 03 | C19: Décompte | D19: 2024/ZESID/TVX - 06 | E19: 693232949 | F19: 34413464 | G19: 653855815 | H19: 248184 | I19: 4715487 | J19: 0 | K19: 124781931 | L19: 818014880 | M19: =ROUND(F19*$B$3,0) -> 6194424 | N19: =ROUND(G19*$B$3,0) -> 117694047 | O19: =ROUND(H19*$B$3,0) -> 44673 | P19: =ROUND(I19*$B$3,0) -> 848788 | Q19: =M19+N19 -> 123888471 | R19: =O19+P19 -> 893461 | S19: =Q19+R19-K19 -> 1 | T19: =IF(C19="Net à payer","",L19-E19-K19-IF(C19="Contrat",J19,0)) -> 0
A20: 45467 | B20: Remboursement avance de démarrage Décompte 03 | C20: Remb. avance démarrage | D20: 2024/ZESID/TVX - 06 | E20: 173308237 | F20: 8603366 | G20: 163463954 | H20: 62046 | I20: 1178872 | J20: 0 | K20: 31195483 | L20: 204503720 | M20: =ROUND(F20*$B$3,0) -> 1548606 | N20: =ROUND(G20*$B$3,0) -> 29423512 | O20: =ROUND(H20*$B$3,0) -> 11168 | P20: =ROUND(I20*$B$3,0) -> 212197 | Q20: =M20+N20 -> 30972118 | R20: =O20+P20 -> 223365 | S20: =Q20+R20-K20 -> 0 | T20: =IF(C20="Net à payer","",L20-E20-K20-IF(C20="Contrat",J20,0)) -> 0
A21: 45467 | B21: Retenue de garantie Décompte 03 | C21: Retenue de garantie | D21: 2024/ZESID/TVX - 06 | E21: 34661647 | F21: 1720673 | G21: 32692791 | H21: 12409 | I21: 235774 | J21: 0 | K21: 6239097 | L21: 40900744 | M21: =ROUND(F21*$B$3,0) -> 309721 | N21: =ROUND(G21*$B$3,0) -> 5884702 | O21: =ROUND(H21*$B$3,0) -> 2234 | P21: =ROUND(I21*$B$3,0) -> 42439 | Q21: =M21+N21 -> 6194423 | R21: =O21+P21 -> 44673 | S21: =Q21+R21-K21 -> -1 | T21: =IF(C21="Net à payer","",L21-E21-K21-IF(C21="Contrat",J21,0)) -> 0
B22: NET A PAYER DECOMPTE 03 | C22: Net à payer | E22: 485263064 | F22: 24089425 | G22: 457699070 | H22: 173728 | I22: 3300841 | J22: 0 | K22: 87347352 | L22: 572610416 | M22: =ROUND(F22*$B$3,0) -> 4336097 | N22: =ROUND(G22*$B$3,0) -> 82385833 | O22: =ROUND(H22*$B$3,0) -> 31271 | P22: =ROUND(I22*$B$3,0) -> 594151 | Q22: =M22+N22 -> 86721930 | R22: =O22+P22 -> 625422 | S22: =Q22+R22-K22 -> 0 | T22: =IF(C22="Net à payer","",L22-E22-K22-IF(C22="Contrat",J22,0))
A23: 45502 | B23: Décompte 04 | C23: Décompte | D23: 2024/ZESID/TVX - 07 | E23: 420602711 | F23: 20844783 | G23: 396050870 | H23: 185353 | I23: 3521705 | J23: 0 | K23: 75708488 | L23: 496311199 | M23: =ROUND(F23*$B$3,0) -> 3752061 | N23: =ROUND(G23*$B$3,0) -> 71289157 | O23: =ROUND(H23*$B$3,0) -> 33364 | P23: =ROUND(I23*$B$3,0) -> 633907 | Q23: =M23+N23 -> 75041218 | R23: =O23+P23 -> 667271 | S23: =Q23+R23-K23 -> 1 | T23: =IF(C23="Net à payer","",L23-E23-K23-IF(C23="Contrat",J23,0)) -> 0
A24: 45502 | B24: Remboursement avance de démarrage Décompte 04 | C24: Remb. avance démarrage | D24: 2024/ZESID/TVX - 07 | E24: 105150678 | F24: 5211196 | G24: 99012718 | H24: 46338 | I24: 880426 | J24: 0 | K24: 18927122 | L24: 124077800 | M24: =ROUND(F24*$B$3,0) -> 938015 | N24: =ROUND(G24*$B$3,0) -> 17822289 | O24: =ROUND(H24*$B$3,0) -> 8341 | P24: =ROUND(I24*$B$3,0) -> 158477 | Q24: =M24+N24 -> 18760304 | R24: =O24+P24 -> 166818 | S24: =Q24+R24-K24 -> 0 | T24: =IF(C24="Net à payer","",L24-E24-K24-IF(C24="Contrat",J24,0)) -> 0
A25: 45502 | B25: Retenue de garantie Décompte 04 | C25: Retenue de garantie | D25: 2024/ZESID/TVX - 07 | E25: 21030136 | F25: 1042239 | G25: 19802544 | H25: 9268 | I25: 176085 | J25: 0 | K25: 3785424 | L25: 24815560 | M25: =ROUND(F25*$B$3,0) -> 187603 | N25: =ROUND(G25*$B$3,0) -> 3564458 | O25: =ROUND(H25*$B$3,0) -> 1668 | P25: =ROUND(I25*$B$3,0) -> 31695 | Q25: =M25+N25 -> 3752061 | R25: =O25+P25 -> 33363 | S25: =Q25+R25-K25 -> 0 | T25: =IF(C25="Net à payer","",L25-E25-K25-IF(C25="Contrat",J25,0)) -> 0
B26: NET A PAYER DECOMPTE 04 | C26: Net à payer | E26: 294421898 | F26: 14591348 | G26: 277235609 | H26: 129747 | I26: 2465194 | J26: 0 | K26: 52995942 | L26: 347417839 | M26: =ROUND(F26*$B$3,0) -> 2626443 | N26: =ROUND(G26*$B$3,0) -> 49902410 | O26: =ROUND(H26*$B$3,0) -> 23354 | P26: =ROUND(I26*$B$3,0) -> 443735 | Q26: =M26+N26 -> 52528853 | R26: =O26+P26 -> 467089 | S26: =Q26+R26-K26 -> 0 | T26: =IF(C26="Net à payer","",L26-E26-K26-IF(C26="Contrat",J26,0))
A27: 45534 | B27: Décompte 05 | C27: Décompte | D27: 2024/ZESID/TVX - 08 | E27: 508529872 | F27: 24309708 | G27: 461884456 | H27: 1116785 | I27: 21218923 | J27: 0 | K27: 91535377 | L27: 600065249 | M27: =ROUND(F27*$B$3,0) -> 4375747 | N27: =ROUND(G27*$B$3,0) -> 83139202 | O27: =ROUND(H27*$B$3,0) -> 201021 | P27: =ROUND(I27*$B$3,0) -> 3819406 | Q27: =M27+N27 -> 87514949 | R27: =O27+P27 -> 4020427 | S27: =Q27+R27-K27 -> -1 | T27: =IF(C27="Net à payer","",L27-E27-K27-IF(C27="Contrat",J27,0)) -> 0
A28: 45534 | B28: Remboursement avance de démarrage Décompte 05 | C28: Remb. avance démarrage | D28: 2024/ZESID/TVX - 08 | E28: 127132468 | F28: 6077427 | G28: 115471114 | H28: 279196 | I28: 5304731 | J28: 0 | K28: 22883844 | L28: 150016312 | M28: =ROUND(F28*$B$3,0) -> 1093937 | N28: =ROUND(G28*$B$3,0) -> 20784801 | O28: =ROUND(H28*$B$3,0) -> 50255 | P28: =ROUND(I28*$B$3,0) -> 954852 | Q28: =M28+N28 -> 21878738 | R28: =O28+P28 -> 1005107 | S28: =Q28+R28-K28 -> 1 | T28: =IF(C28="Net à payer","",L28-E28-K28-IF(C28="Contrat",J28,0)) -> 0
A29: 45534 | B29: Retenue de garantie Décompte 05 | C29: Retenue de garantie | D29: 2024/ZESID/TVX - 08 | E29: 25426494 | F29: 1215485 | G29: 23094223 | H29: 55839 | I29: 1060946 | J29: 0 | K29: 4576769 | L29: 30003262 | M29: =ROUND(F29*$B$3,0) -> 218787 | N29: =ROUND(G29*$B$3,0) -> 4156960 | O29: =ROUND(H29*$B$3,0) -> 10051 | P29: =ROUND(I29*$B$3,0) -> 190970 | Q29: =M29+N29 -> 4375747 | R29: =O29+P29 -> 201021 | S29: =Q29+R29-K29 -> -1 | T29: =IF(C29="Net à payer","",L29-E29-K29-IF(C29="Contrat",J29,0)) -> -1
B30: NET A PAYER DECOMPTE 05 | C30: Net à payer | E30: 355970910 | F30: 17016796 | G30: 323319119 | H30: 781750 | I30: 14853246 | J30: 0 | K30: 64074764 | L30: 420045674 | M30: =ROUND(F30*$B$3,0) -> 3063023 | N30: =ROUND(G30*$B$3,0) -> 58197441 | O30: =ROUND(H30*$B$3,0) -> 140715 | P30: =ROUND(I30*$B$3,0) -> 2673584 | Q30: =M30+N30 -> 61260464 | R30: =O30+P30 -> 2814299 | S30: =Q30+R30-K30 -> -1 | T30: =IF(C30="Net à payer","",L30-E30-K30-IF(C30="Contrat",J30,0))
A31: 45595 | B31: Décompte 06 | C31: Décompte | D31: 2024/ZESID/TVX - 09 | E31: 676686959 | F31: 33402436 | G31: 634646290 | H31: 431912 | I31: 8206321 | J31: 0 | K31: 121803653 | L31: 798490612 | M31: =ROUND(F31*$B$3,0) -> 6012438 | N31: =ROUND(G31*$B$3,0) -> 114236332 | O31: =ROUND(H31*$B$3,0) -> 77744 | P31: =ROUND(I31*$B$3,0) -> 1477138 | Q31: =M31+N31 -> 120248770 | R31: =O31+P31 -> 1554882 | S31: =Q31+R31-K31 -> -1 | T31: =IF(C31="Net à payer","",L31-E31-K31-IF(C31="Contrat",J31,0)) -> 0
A32: 45595 | B32: Remboursement avance de démarrage Décompte 06 | C32: Remb. avance démarrage | D32: 2024/ZESID/TVX - 09 | E32: 169171740 | F32: 8350609 | G32: 158661572 | H32: 107978 | I32: 2051580 | J32: 0 | K32: 30450913 | L32: 199622653 | M32: =ROUND(F32*$B$3,0) -> 1503110 | N32: =ROUND(G32*$B$3,0) -> 28559083 | O32: =ROUND(H32*$B$3,0) -> 19436 | P32: =ROUND(I32*$B$3,0) -> 369284 | Q32: =M32+N32 -> 30062193 | R32: =O32+P32 -> 388720 | S32: =Q32+R32-K32 -> 0 | T32: =IF(C32="Net à payer","",L32-E32-K32-IF(C32="Contrat",J32,0)) -> 0
A33: 45595 | B33: Retenue de garantie Décompte 06 | C33: Retenue de garantie | D33: 2024/ZESID/TVX - 09 | E33: 33834348 | F33: 1670122 | G33: 31732314 | H33: 21596 | I33: 410316 | J33: 0 | K33: 6090183 | L33: 39924531 | M33: =ROUND(F33*$B$3,0) -> 300622 | N33: =ROUND(G33*$B$3,0) -> 5711817 | O33: =ROUND(H33*$B$3,0) -> 3887 | P33: =ROUND(I33*$B$3,0) -> 73857 | Q33: =M33+N33 -> 6012439 | R33: =O33+P33 -> 77744 | S33: =Q33+R33-K33 -> 0 | T33: =IF(C33="Net à payer","",L33-E33-K33-IF(C33="Contrat",J33,0)) -> 0
B34: NET A PAYER DECOMPTE 06 | C34: Net à payer | E34: 473680871 | F34: 23381705 | G34: 444252403 | H34: 302338 | I34: 5744425 | J34: 0 | K34: 85262557 | L34: 558943428 | M34: =ROUND(F34*$B$3,0) -> 4208707 | N34: =ROUND(G34*$B$3,0) -> 79965433 | O34: =ROUND(H34*$B$3,0) -> 54421 | P34: =ROUND(I34*$B$3,0) -> 1033997 | Q34: =M34+N34 -> 84174140 | R34: =O34+P34 -> 1088418 | S34: =Q34+R34-K34 -> 1 | T34: =IF(C34="Net à payer","",L34-E34-K34-IF(C34="Contrat",J34,0))
A35: 45610 | B35: Décompte 07 | C35: Décompte | D35: 2024/ZESID/TVX - 10 | E35: 643846121 | F35: 30992978 | G35: 588866573 | H35: 1199329 | I35: 22787242 | J35: 0 | K35: 115892302 | L35: 759738423 | M35: =ROUND(F35*$B$3,0) -> 5578736 | N35: =ROUND(G35*$B$3,0) -> 105995983 | O35: =ROUND(H35*$B$3,0) -> 215879 | P35: =ROUND(I35*$B$3,0) -> 4101704 | Q35: =M35+N35 -> 111574719 | R35: =O35+P35 -> 4317583 | S35: =Q35+R35-K35 -> 0 | T35: =IF(C35="Net à payer","",L35-E35-K35-IF(C35="Contrat",J35,0)) -> 0
A36: 45610 | B36: Remboursement avance de démarrage Décompte 07 | C36: Remb. avance démarrage | D36: 2024/ZESID/TVX - 10 | E36: 160961530 | F36: 7748244 | G36: 147216643 | H36: 299832 | I36: 5696810 | J36: 0 | K36: 28973075 | L36: 189934606 | M36: =ROUND(F36*$B$3,0) -> 1394684 | N36: =ROUND(G36*$B$3,0) -> 26498996 | O36: =ROUND(H36*$B$3,0) -> 53970 | P36: =ROUND(I36*$B$3,0) -> 1025426 | Q36: =M36+N36 -> 27893680 | R36: =O36+P36 -> 1079396 | S36: =Q36+R36-K36 -> 1 | T36: =IF(C36="Net à payer","",L36-E36-K36-IF(C36="Contrat",J36,0)) -> 1
A37: 45610 | B37: Retenue de garantie Décompte 07 | C37: Retenue de garantie | D37: 2024/ZESID/TVX - 10 | E37: 32192306 | F37: 1549649 | G37: 29443329 | H37: 59966 | I37: 1139362 | J37: 0 | K37: 5794615 | L37: 37986921 | M37: =ROUND(F37*$B$3,0) -> 278937 | N37: =ROUND(G37*$B$3,0) -> 5299799 | O37: =ROUND(H37*$B$3,0) -> 10794 | P37: =ROUND(I37*$B$3,0) -> 205085 | Q37: =M37+N37 -> 5578736 | R37: =O37+P37 -> 215879 | S37: =Q37+R37-K37 -> 0 | T37: =IF(C37="Net à payer","",L37-E37-K37-IF(C37="Contrat",J37,0)) -> 0
B38: NET A PAYER DECOMPTE 07 | C38: Net à payer | E38: 450692285 | F38: 21695084 | G38: 412206601 | H38: 839530 | I38: 15951069 | J38: 0 | K38: 81124611 | L38: 531816896 | M38: =ROUND(F38*$B$3,0) -> 3905115 | N38: =ROUND(G38*$B$3,0) -> 74197188 | O38: =ROUND(H38*$B$3,0) -> 151115 | P38: =ROUND(I38*$B$3,0) -> 2871192 | Q38: =M38+N38 -> 78102303 | R38: =O38+P38 -> 3022307 | S38: =Q38+R38-K38 -> -1 | T38: =IF(C38="Net à payer","",L38-E38-K38-IF(C38="Contrat",J38,0))
A39: 45611 | B39: Acompte sur approvisionnement n°01 - part 01 | C39: Acompte appro | D39: 2024/ZESID/TVX - 11 | E39: 1355000000 | F39: 47425000 | G39: 901075000 | H39: 20325000 | I39: 386175000 | J39: 0 | K39: 243900000 | L39: 1598900000 | M39: =ROUND(F39*$B$3,0) -> 8536500 | N39: =ROUND(G39*$B$3,0) -> 162193500 | O39: =ROUND(H39*$B$3,0) -> 3658500 | P39: =ROUND(I39*$B$3,0) -> 69511500 | Q39: =M39+N39 -> 170730000 | R39: =O39+P39 -> 73170000 | S39: =Q39+R39-K39 -> 0 | T39: =IF(C39="Net à payer","",L39-E39-K39-IF(C39="Contrat",J39,0)) -> 0
A40: 45611 | B40: Acompte sur approvisionnement n°01 - part 02 | C40: Acompte appro | D40: 2024/ZESID/TVX - 12 | E40: 1419700000 | F40: 49689500 | G40: 944100500 | H40: 21295500 | I40: 404614500 | J40: 0 | K40: 255546000 | L40: 1675246000 | M40: =ROUND(F40*$B$3,0) -> 8944110 | N40: =ROUND(G40*$B$3,0) -> 169938090 | O40: =ROUND(H40*$B$3,0) -> 3833190 | P40: =ROUND(I40*$B$3,0) -> 72830610 | Q40: =M40+N40 -> 178882200 | R40: =O40+P40 -> 76663800 | S40: =Q40+R40-K40 -> 0 | T40: =IF(C40="Net à payer","",L40-E40-K40-IF(C40="Contrat",J40,0)) -> 0
B41: NET A PAYER ACOMPTE APPROVISIONNEMENT N°01 & N°02 | C41: Net à payer | E41: 2774700000 | F41: 97114500 | G41: 1845175500 | H41: 41620500 | I41: 790789500 | J41: 0 | K41: 499446000 | L41: 3274146000 | M41: =ROUND(F41*$B$3,0) -> 17480610 | N41: =ROUND(G41*$B$3,0) -> 332131590 | O41: =ROUND(H41*$B$3,0) -> 7491690 | P41: =ROUND(I41*$B$3,0) -> 142342110 | Q41: =M41+N41 -> 349612200 | R41: =O41+P41 -> 149833800 | S41: =Q41+R41-K41 -> 0 | T41: =IF(C41="Net à payer","",L41-E41-K41-IF(C41="Contrat",J41,0))
...

Sheet Synthèse TVA
A1: SYNTHÈSE DE LA TVA PAR CATÉGORIE ET PAR ENTREPRISE (FCFA)
A2: Calculé par SOMME.SI.ENS sur l'onglet « Fiche décompte » (lignes « Net à payer » et totaux exclus).
A4: Catégorie | B4: Montant HT/HD | C4: TVA SERTEM État | D4: TVA SERTEM BOAD | E4: TVA DIASS État | F4: TVA DIASS BOAD | G4: TVA SERTEM | H4: TVA DIASS | I4: TVA totale éclatée | J4: TVA fiche | K4: Écart
A5: Avance démarrage | B5: =SUMIFS('Fiche décompte'!$E$8:$E$79,'Fiche décompte'!$C$8:$C$79,$A5) -> 5549400000 | C5: =SUMIFS('Fiche décompte'!$M$8:$M$79,'Fiche décompte'!$C$8:$C$79,$A5) -> 34961220 | D5: =SUMIFS('Fiche décompte'!$N$8:$N$79,'Fiche décompte'!$C$8:$C$79,$A5) -> 664263180 | E5: =SUMIFS('Fiche décompte'!$O$8:$O$79,'Fiche décompte'!$C$8:$C$79,$A5) -> 14983380 | F5: =SUMIFS('Fiche décompte'!$P$8:$P$79,'Fiche décompte'!$C$8:$C$79,$A5) -> 284684220 | G5: =SUMIFS('Fiche décompte'!$Q$8:$Q$79,'Fiche décompte'!$C$8:$C$79,$A5) -> 699224400 | H5: =SUMIFS('Fiche décompte'!$R$8:$R$79,'Fiche décompte'!$C$8:$C$79,$A5) -> 299667600 | I5: =G5+H5 -> 998892000 | J5: =SUMIFS('Fiche décompte'!$K$8:$K$79,'Fiche décompte'!$C$8:$C$79,$A5) -> 998892000 | K5: =I5-J5 -> 0
A6: Décompte | B6: =SUMIFS('Fiche décompte'!$E$8:$E$79,'Fiche décompte'!$C$8:$C$79,$A6) -> 10977747877 | C6: =SUMIFS('Fiche décompte'!$M$8:$M$79,'Fiche décompte'!$C$8:$C$79,$A6) -> 71868332 | D6: =SUMIFS('Fiche décompte'!$N$8:$N$79,'Fiche décompte'!$C$8:$C$79,$A6) -> 1365498339 | E6: =SUMIFS('Fiche décompte'!$O$8:$O$79,'Fiche décompte'!$C$8:$C$79,$A6) -> 26931397 | F6: =SUMIFS('Fiche décompte'!$P$8:$P$79,'Fiche décompte'!$C$8:$C$79,$A6) -> 511696551 | G6: =SUMIFS('Fiche décompte'!$Q$8:$Q$79,'Fiche décompte'!$C$8:$C$79,$A6) -> 1437366671 | H6: =SUMIFS('Fiche décompte'!$R$8:$R$79,'Fiche décompte'!$C$8:$C$79,$A6) -> 538627948 | I6: =G6+H6 -> 1975994619 | J6: =SUMIFS('Fiche décompte'!$K$8:$K$79,'Fiche décompte'!$C$8:$C$79,$A6) -> 1975994620 | K6: =I6-J6 -> -1
A7: Remb. avance démarrage | B7: =SUMIFS('Fiche décompte'!$E$8:$E$79,'Fiche décompte'!$C$8:$C$79,$A7) -> 2744436971 | C7: =SUMIFS('Fiche décompte'!$M$8:$M$79,'Fiche décompte'!$C$8:$C$79,$A7) -> 17967085 | D7: =SUMIFS('Fiche décompte'!$N$8:$N$79,'Fiche décompte'!$C$8:$C$79,$A7) -> 341374584 | E7: =SUMIFS('Fiche décompte'!$O$8:$O$79,'Fiche décompte'!$C$8:$C$79,$A7) -> 6732849 | F7: =SUMIFS('Fiche décompte'!$P$8:$P$79,'Fiche décompte'!$C$8:$C$79,$A7) -> 127924139 | G7: =SUMIFS('Fiche décompte'!$Q$8:$Q$79,'Fiche décompte'!$C$8:$C$79,$A7) -> 359341669 | H7: =SUMIFS('Fiche décompte'!$R$8:$R$79,'Fiche décompte'!$C$8:$C$79,$A7) -> 134656988 | I7: =G7+H7 -> 493998657 | J7: =SUMIFS('Fiche décompte'!$K$8:$K$79,'Fiche décompte'!$C$8:$C$79,$A7) -> 492328403 | K7: =I7-J7 -> 1670254
A8: Retenue de garantie | B8: =SUMIFS('Fiche décompte'!$E$8:$E$79,'Fiche décompte'!$C$8:$C$79,$A8) -> 548887396 | C8: =SUMIFS('Fiche décompte'!$M$8:$M$79,'Fiche décompte'!$C$8:$C$79,$A8) -> 3593417 | D8: =SUMIFS('Fiche décompte'!$N$8:$N$79,'Fiche décompte'!$C$8:$C$79,$A8) -> 68274918 | E8: =SUMIFS('Fiche décompte'!$O$8:$O$79,'Fiche décompte'!$C$8:$C$79,$A8) -> 1346570 | F8: =SUMIFS('Fiche décompte'!$P$8:$P$79,'Fiche décompte'!$C$8:$C$79,$A8) -> 25584826 | G8: =SUMIFS('Fiche décompte'!$Q$8:$Q$79,'Fiche décompte'!$C$8:$C$79,$A8) -> 71868335 | H8: =SUMIFS('Fiche décompte'!$R$8:$R$79,'Fiche décompte'!$C$8:$C$79,$A8) -> 26931396 | I8: =G8+H8 -> 98799731 | J8: =SUMIFS('Fiche décompte'!$K$8:$K$79,'Fiche décompte'!$C$8:$C$79,$A8) -> 98799732 | K8: =I8-J8 -> -1
A9: Acompte appro | B9: =SUMIFS('Fiche décompte'!$E$8:$E$79,'Fiche décompte'!$C$8:$C$79,$A9) -> 5549400000 | C9: =SUMIFS('Fiche décompte'!$M$8:$M$79,'Fiche décompte'!$C$8:$C$79,$A9) -> 34961220 | D9: =SUMIFS('Fiche décompte'!$N$8:$N$79,'Fiche décompte'!$C$8:$C$79,$A9) -> 664263180 | E9: =SUMIFS('Fiche décompte'!$O$8:$O$79,'Fiche décompte'!$C$8:$C$79,$A9) -> 14983380 | F9: =SUMIFS('Fiche décompte'!$P$8:$P$79,'Fiche décompte'!$C$8:$C$79,$A9) -> 284684220 | G9: =SUMIFS('Fiche décompte'!$Q$8:$Q$79,'Fiche décompte'!$C$8:$C$79,$A9) -> 699224400 | H9: =SUMIFS('Fiche décompte'!$R$8:$R$79,'Fiche décompte'!$C$8:$C$79,$A9) -> 299667600 | I9: =G9+H9 -> 998892000 | J9: =SUMIFS('Fiche décompte'!$K$8:$K$79,'Fiche décompte'!$C$8:$C$79,$A9) -> 998892000 | K9: =I9-J9 -> 0
A10: Remb. acompte appro | B10: =SUMIFS('Fiche décompte'!$E$8:$E$79,'Fiche décompte'!$C$8:$C$79,$A10) -> 1458755037 | C10: =SUMIFS('Fiche décompte'!$M$8:$M$79,'Fiche décompte'!$C$8:$C$79,$A10) -> 6999154 | D10: =SUMIFS('Fiche décompte'!$N$8:$N$79,'Fiche décompte'!$C$8:$C$79,$A10) -> 132983919 | E10: =SUMIFS('Fiche décompte'!$O$8:$O$79,'Fiche décompte'!$C$8:$C$79,$A10) -> 6129642 | F10: =SUMIFS('Fiche décompte'!$P$8:$P$79,'Fiche décompte'!$C$8:$C$79,$A10) -> 116463193 | G10: =SUMIFS('Fiche décompte'!$Q$8:$Q$79,'Fiche décompte'!$C$8:$C$79,$A10) -> 139983073 | H10: =SUMIFS('Fiche décompte'!$R$8:$R$79,'Fiche décompte'!$C$8:$C$79,$A10) -> 122592835 | I10: =G10+H10 -> 262575908 | J10: =SUMIFS('Fiche décompte'!$K$8:$K$79,'Fiche décompte'!$C$8:$C$79,$A10) -> 262575907 | K10: =I10-J10 -> 1
A12: TVA avance de démarrage restant à rembourser | B12: =B5-B7 -> 2804963029 | C12: =C5-C7 -> 16994135 | D12: =D5-D7 -> 322888596 | E12: =E5-E7 -> 8250531 | F12: =F5-F7 -> 156760081 | G12: =G5-G7 -> 339882731 | H12: =H5-H7 -> 165010612 | I12: =I5-I7 -> 504893343 | ... K12: =K5-K7 -> -1670254
A13: TVA acomptes appro restant à rembourser | B13: =B9-B10 -> 4090644963 | C13: =C9-C10 -> 27962066 | D13: =D9-D10 -> 531279261 | E13: =E9-E10 -> 8853738 | F13: =F9-F10 -> 168221027 | G13: =G9-G10 -> 559241327 | H13: =H9-H10 -> 177074765 | I13: =I9-I10 -> 736316092 | ... K13: =K9-K10 -> -1
A15: Nota : sur la ligne « Remb. avance démarrage » du décompte 01, la TVA de la fiche (31 599 292) ne correspond pas à 18 % du HT (33 269 543) — d'où l'écart de 1 670 251 XOF.
